Workbook

Sheet Лист1
A1: ФИО | B1: КВ | C1: Столбец1 | D1: кол-во голосов | E1: вопрос 1 | F1: вопрос 2 | G1: вопрос 3 | H1: вопрос 4 | I1: вопрос 5 | J1: вопрос 6 | K1: вопрос 7 | L1: вопрос 8 | M1: вопрос 9 | N1: вопрос 10 | O1: вопрос 11 | P1: вопрос 12
A2: Музалевская Вера Геннадьевна | B2: 1 | C2: 163 | D2: =C2/100 -> 1.63 | E2: за | F2: за | G2: за | H2: за | I2: воздержался | J2: за | K2: за | L2: против | M2: против | N2: воздержался | O2: за | P2: против
A3: Музалевский Юрий Сергеевич | B3: 1 | C3: 163 | D3: =C3/100 -> 1.63 | E3: за | F3: за | G3: за | H3: за | I3: воздержался | J3: за | K3: за | L3: против | M3: против | N3: воздержался | O3: за | P3: против
A4: Гейко Антонина Ивановна | B4: 2 | C4: 200 | D4: =C4/100 -> 2 | E4: за | F4: за | G4: за | H4: за | I4: за | J4: за | K4: за | L4: против | M4: против | N4: против | O4: за | P4: за
A5: Морозова Екатерина Сергеевна | B5: 3 | C5: 204 | D5: =C5/100 -> 2.04 | E5: за | F5: за | G5: за | H5: за | I5: за | J5: за | K5: за | L5: против | M5: против | N5: воздержался | O5: за | P5: за
A6: Николаева Екатерина Сергеевна | B6: 4 | C6: 151 | D6: =C6/100 -> 1.51 | E6: за | F6: за | G6: воздержался | H6: воздержался | I6: воздержался | J6: воздержался | K6: за | L6: против | M6: воздержался | N6: воздержался | O6: за | P6: за
A7: Великих Павел Владимирович | B7: 4 | C7: 151 | D7: =C7/100 -> 1.51 | E7: за | F7: за | G7: воздержался | H7: воздержался | I7: воздержался | J7: воздержался | K7: за | L7: против | M7: воздержался | N7: воздержался | O7: за | P7: за
A8: Мамаенко Даниил Евгеньевич | B8: 5 | C8: 215 | D8: =C8/100 -> 2.15 | E8: за | F8: за | G8: за | H8: за | I8: за | J8: за | K8: воздержался | L8: воздержался | M8: воздержался | N8: за | O8: за | P8: за
A9: Бугров Дмитрий Геннадьевич | B9: 6 | C9: 136 | D9: =C9/100 -> 1.36 | E9: за | F9: за | G9: за | H9: за | I9: за | J9: за | K9: за | L9: против | M9: против | N9: против | O9: за | P9: за
A10: Бугрова Татьяна Федоровна | B10: 6 | C10: 136 | D10: =C10/100 -> 1.36 | E10: за | F10: за | G10: за | H10: за | I10: за | J10: за | K10: за | L10: против | M10: против | N10: против | O10: за | P10: за
A11: Годунов Виктор Александрович | B11: 7 | C11: 160 | D11: =C11/100 -> 1.6 | E11: за | F11: воздержался | G11: за | H11: за | I11: за | J11: за | K11: за | L11: против | M11: против | N11: против | O11: за | P11: за
A12: Годунова Арина Андреевна | B12: 7 | C12: 160 | D12: =C12/100 -> 1.6 | E12: за | F12: воздержался | G12: за | H12: за | I12: за | J12: за | K12: за | L12: против | M12: против | N12: против | O12: за | P12: за
A13: Шиляев Антон Николаевич | B13: 8 | C13: 200 | D13: =C13/100 -> 2
A14: Колесникова Татьяна Леонидовна | B14: 9 | C14: 200 | D14: =C14/100 -> 2 | E14: против | F14: за | G14: против | H14: за | I14: против | J14: против | K14: за | L14: против | M14: против | N14: против | O14: за | P14: против
A15: Комаров Сергей Валерьевич | B15: 10 | C15: 151 | D15: =C15/100 -> 1.51 | E15: за | F15: за | G15: за | H15: за | I15: за | J15: за | K15: за | L15: за | M15: за | N15: за | O15: за | P15: за
A16: Комарова Виктория Викторовна | B16: 10 | C16: 151 | D16: =C16/100 -> 1.51 | E16: за | F16: за | G16: за | H16: за | I16: за | J16: за | K16: за | L16: за | M16: за | N16: за | O16: за | P16: за
A17: Кирова Елена Александровна | B17: 11 | C17: 43 | D17: =C17/100 -> 0.43 | E17: против | F17: воздержался | G17: воздержался | H17: воздержался | I17: против | J17: против | K17: за | L17: против | M17: против | N17: воздержался | O17: за | P17: воздержался
A18: Демян Владислав Иванович | B18: 11 | C18: 43 | D18: =C18/100 -> 0.43 | E18: против | F18: воздержался | G18: воздержался | H18: воздержался | I18: против | J18: против | K18: за | L18: против | M18: против | N18: воздержался | O18: за | P18: воздержался
A19: Демян Матвей Иванович | B19: 11 | C19: 43 | D19: =C19/100 -> 0.43 | E19: против | F19: воздержался | G19: воздержался | H19: воздержался | I19: против | J19: против | K19: за | L19: против | M19: против | N19: воздержался | O19: за | P19: воздержался
A20: Авдеева Ксения Александровна | B20: 11 | C20: 43 | D20: =C20/100 -> 0.43 | E20: против | F20: воздержался | G20: воздержался | H20: воздержался | I20: против | J20: против | K20: за | L20: против | M20: против | N20: воздержался | O20: за | P20: воздержался
A21: Демян Виктория Ивановна | B21: 11 | C21: 43 | D21: =C21/100 -> 0.43 | E21: против | F21: воздержался | G21: воздержался | H21: воздержался | I21: против | J21: против | K21: за | L21: против | M21: против | N21: воздержался | O21: за | P21: воздержался
A22: Кизилова Марина Владмировна | B22: 12 | C22: 136 | D22: =C22/100 -> 1.36
A23: Ипатов Андрей Викторович | B23: 12 | C23: 136 | D23: =C23/100 -> 1.36
A24: Андержанова Лилия Рустамовна | B24: 13 | C24: 323 | D24: =C24/100 -> 3.23 | E24: за | F24: за | G24: за | H24: за | I24: за | J24: за | K24: за | L24: за | M24: за | N24: за | O24: за | P24: за
A25: Самохина Елена Анатольевна | B25: 14 | C25: 200 | D25: =C25/100 -> 2
A26: Козырь Александр Александрович | B26: 15 | C26: 202 | D26: =C26/100 -> 2.02
A27: Козырь Александр Александрович | B27: 16 | C27: 299 | D27: =C27/100 -> 2.99
A28: Капустина Марина Вламировна | B28: 17 | C28: 214 | D28: =C28/100 -> 2.14 | E28: за | F28: за | G28: за | H28: за | I28: за | J28: за | K28: за | L28: против | M28: против | N28: против | O28: за | P28: за
A29: Алимов Анатолий Анатольевич | B29: 18 | C29: 134 | D29: =C29/100 -> 1.34 | E29: за | F29: за | G29: за | H29: за | I29: за | J29: за | K29: за | L29: за | M29: за | N29: за | O29: за | P29: за
A30: Алимова Людмила Ивановна | B30: 18 | C30: 134 | D30: =C30/100 -> 1.34 | E30: за | F30: за | G30: за | H30: за | I30: за | J30: за | K30: за | L30: за | M30: за | N30: за | O30: за | P30: за
A31: Мельник Дмитрий Дмитриевич | B31: 19 | C31: 162 | D31: =C31/100 -> 1.62
A32: Мельник Виктория Александровна | B32: 19 | C32: 162 | D32: =C32/100 -> 1.62
A33: Марченко Ольга Васильевна | B33: 20 | C33: 199 | D33: =C33/100 -> 1.99
A34: Батова Валентина Владимировна | B34: 21 | C34: 101 | D34: =C34/100 -> 1.01
A35: Бададгулов Георгий Александрович | B35: 21 | C35: 101 | D35: =C35/100 -> 1.01
A36: Гарин Иван Николаевич | B36: 22 | C36: 298 | D36: =C36/100 -> 2.98
A37: Искандарян Нара | B37: 23 | C37: 211 | D37: =C37/100 -> 2.11
A38: Шляк Евгений Вадимович | B38: 24 | C38: 134 | D38: =C38/100 -> 1.34 | E38: за | F38: за | G38: за | H38: за | I38: за | J38: за | K38: за | L38: за | M38: за | N38: за | O38: за | P38: за
A39: Шляк Екатерина Александровна | B39: 24 | C39: 134 | D39: =C39/100 -> 1.34 | E39: за | F39: за | G39: за | H39: за | I39: за | J39: за | K39: за | L39: за | M39: за | N39: за | O39: за | P39: за
A40: Макарова Марина Валерьевна | B40: 25 | C40: 97 | D40: =C40/100 -> 0.97
...

Sheet Лист2
A1: за
A2: против
A3: воздержался

Sheet наличие голоса
A1: =IF(NOT(ISBLANK(Лист1!E2)),Лист1!$D2,0) -> 1.63 | B1: =IF(NOT(ISBLANK(Лист1!F2)),Лист1!$D2,0) -> 1.63 | C1: =IF(NOT(ISBLANK(Лист1!G2)),Лист1!$D2,0) -> 1.63 | D1: =IF(NOT(ISBLANK(Лист1!H2)),Лист1!$D2,0) -> 1.63 | E1: =IF(NOT(ISBLANK(Лист1!I2)),Лист1!$D2,0) -> 1.63 | F1: =IF(NOT(ISBLANK(Лист1!J2)),Лист1!$D2,0) -> 1.63 | G1: =IF(NOT(ISBLANK(Лист1!K2)),Лист1!$D2,0) -> 1.63 | H1: =IF(NOT(ISBLANK(Лист1!L2)),Лист1!$D2,0) -> 1.63 | ... L1: =IF(NOT(ISBLANK(Лист1!P2)),Лист1!$D2,0) -> 1.63
A2: =IF(NOT(ISBLANK(Лист1!E3)),Лист1!$D3,0) -> 1.63 | B2: =IF(NOT(ISBLANK(Лист1!F3)),Лист1!$D3,0) -> 1.63 | C2: =IF(NOT(ISBLANK(Лист1!G3)),Лист1!$D3,0) -> 1.63 | D2: =IF(NOT(ISBLANK(Лист1!H3)),Лист1!$D3,0) -> 1.63 | E2: =IF(NOT(ISBLANK(Лист1!I3)),Лист1!$D3,0) -> 1.63 | F2: =IF(NOT(ISBLANK(Лист1!J3)),Лист1!$D3,0) -> 1.63 | G2: =IF(NOT(ISBLANK(Лист1!K3)),Лист1!$D3,0) -> 1.63 | H2: =IF(NOT(ISBLANK(Лист1!L3)),Лист1!$D3,0) -> 1.63 | ... L2: =IF(NOT(ISBLANK(Лист1!P3)),Лист1!$D3,0) -> 1.63
A3: =IF(NOT(ISBLANK(Лист1!E4)),Лист1!$D4,0) -> 2 | B3: =IF(NOT(ISBLANK(Лист1!F4)),Лист1!$D4,0) -> 2 | C3: =IF(NOT(ISBLANK(Лист1!G4)),Лист1!$D4,0) -> 2 | D3: =IF(NOT(ISBLANK(Лист1!H4)),Лист1!$D4,0) -> 2 | E3: =IF(NOT(ISBLANK(Лист1!I4)),Лист1!$D4,0) -> 2 | F3: =IF(NOT(ISBLANK(Лист1!J4)),Лист1!$D4,0) -> 2 | G3: =IF(NOT(ISBLANK(Лист1!K4)),Лист1!$D4,0) -> 2 | H3: =IF(NOT(ISBLANK(Лист1!L4)),Лист1!$D4,0) -> 2 | ... L3: =IF(NOT(ISBLANK(Лист1!P4)),Лист1!$D4,0) -> 2
A4: =IF(NOT(ISBLANK(Лист1!E5)),Лист1!$D5,0) -> 2.04 | B4: =IF(NOT(ISBLANK(Лист1!F5)),Лист1!$D5,0) -> 2.04 | C4: =IF(NOT(ISBLANK(Лист1!G5)),Лист1!$D5,0) -> 2.04 | D4: =IF(NOT(ISBLANK(Лист1!H5)),Лист1!$D5,0) -> 2.04 | E4: =IF(NOT(ISBLANK(Лист1!I5)),Лист1!$D5,0) -> 2.04 | F4: =IF(NOT(ISBLANK(Лист1!J5)),Лист1!$D5,0) -> 2.04 | G4: =IF(NOT(ISBLANK(Лист1!K5)),Лист1!$D5,0) -> 2.04 | H4: =IF(NOT(ISBLANK(Лист1!L5)),Лист1!$D5,0) -> 2.04 | ... L4: =IF(NOT(ISBLANK(Лист1!P5)),Лист1!$D5,0) -> 2.04
A5: =IF(NOT(ISBLANK(Лист1!E6)),Лист1!$D6,0) -> 1.51 | B5: =IF(NOT(ISBLANK(Лист1!F6)),Лист1!$D6,0) -> 1.51 | C5: =IF(NOT(ISBLANK(Лист1!G6)),Лист1!$D6,0) -> 1.51 | D5: =IF(NOT(ISBLANK(Лист1!H6)),Лист1!$D6,0) -> 1.51 | E5: =IF(NOT(ISBLANK(Лист1!I6)),Лист1!$D6,0) -> 1.51 | F5: =IF(NOT(ISBLANK(Лист1!J6)),Лист1!$D6,0) -> 1.51 | G5: =IF(NOT(ISBLANK(Лист1!K6)),Лист1!$D6,0) -> 1.51 | H5: =IF(NOT(ISBLANK(Лист1!L6)),Лист1!$D6,0) -> 1.51 | ... L5: =IF(NOT(ISBLANK(Лист1!P6)),Лист1!$D6,0) -> 1.51
A6: =IF(NOT(ISBLANK(Лист1!E7)),Лист1!$D7,0) -> 1.51 | B6: =IF(NOT(ISBLANK(Лист1!F7)),Лист1!$D7,0) -> 1.51 | C6: =IF(NOT(ISBLANK(Лист1!G7)),Лист1!$D7,0) -> 1.51 | D6: =IF(NOT(ISBLANK(Лист1!H7)),Лист1!$D7,0) -> 1.51 | E6: =IF(NOT(ISBLANK(Лист1!I7)),Лист1!$D7,0) -> 1.51 | F6: =IF(NOT(ISBLANK(Лист1!J7)),Лист1!$D7,0) -> 1.51 | G6: =IF(NOT(ISBLANK(Лист1!K7)),Лист1!$D7,0) -> 1.51 | H6: =IF(NOT(ISBLANK(Лист1!L7)),Лист1!$D7,0) -> 1.51 | ... L6: =IF(NOT(ISBLANK(Лист1!P7)),Лист1!$D7,0) -> 1.51
A7: =IF(NOT(ISBLANK(Лист1!E8)),Лист1!$D8,0) -> 2.15 | B7: =IF(NOT(ISBLANK(Лист1!F8)),Лист1!$D8,0) -> 2.15 | C7: =IF(NOT(ISBLANK(Лист1!G8)),Лист1!$D8,0) -> 2.15 | D7: =IF(NOT(ISBLANK(Лист1!H8)),Лист1!$D8,0) -> 2.15 | E7: =IF(NOT(ISBLANK(Лист1!I8)),Лист1!$D8,0) -> 2.15 | F7: =IF(NOT(ISBLANK(Лист1!J8)),Лист1!$D8,0) -> 2.15 | G7: =IF(NOT(ISBLANK(Лист1!K8)),Лист1!$D8,0) -> 2.15 | H7: =IF(NOT(ISBLANK(Лист1!L8)),Лист1!$D8,0) -> 2.15 | ... L7: =IF(NOT(ISBLANK(Лист1!P8)),Лист1!$D8,0) -> 2.15
A8: =IF(NOT(ISBLANK(Лист1!E9)),Лист1!$D9,0) -> 1.36 | B8: =IF(NOT(ISBLANK(Лист1!F9)),Лист1!$D9,0) -> 1.36 | C8: =IF(NOT(ISBLANK(Лист1!G9)),Лист1!$D9,0) -> 1.36 | D8: =IF(NOT(ISBLANK(Лист1!H9)),Лист1!$D9,0) -> 1.36 | E8: =IF(NOT(ISBLANK(Лист1!I9)),Лист1!$D9,0) -> 1.36 | F8: =IF(NOT(ISBLANK(Лист1!J9)),Лист1!$D9,0) -> 1.36 | G8: =IF(NOT(ISBLANK(Лист1!K9)),Лист1!$D9,0) -> 1.36 | H8: =IF(NOT(ISBLANK(Лист1!L9)),Лист1!$D9,0) -> 1.36 | ... L8: =IF(NOT(ISBLANK(Лист1!P9)),Лист1!$D9,0) -> 1.36
A9: =IF(NOT(ISBLANK(Лист1!E10)),Лист1!$D10,0) -> 1.36 | B9: =IF(NOT(ISBLANK(Лист1!F10)),Лист1!$D10,0) -> 1.36 | C9: =IF(NOT(ISBLANK(Лист1!G10)),Лист1!$D10,0) -> 1.36 | D9: =IF(NOT(ISBLANK(Лист1!H10)),Лист1!$D10,0) -> 1.36 | E9: =IF(NOT(ISBLANK(Лист1!I10)),Лист1!$D10,0) -> 1.36 | F9: =IF(NOT(ISBLANK(Лист1!J10)),Лист1!$D10,0) -> 1.36 | G9: =IF(NOT(ISBLANK(Лист1!K10)),Лист1!$D10,0) -> 1.36 | H9: =IF(NOT(ISBLANK(Лист1!L10)),Лист1!$D10,0) -> 1.36 | ... L9: =IF(NOT(ISBLANK(Лист1!P10)),Лист1!$D10,0) -> 1.36
A10: =IF(NOT(ISBLANK(Лист1!E11)),Лист1!$D11,0) -> 1.6 | B10: =IF(NOT(ISBLANK(Лист1!F11)),Лист1!$D11,0) -> 1.6 | C10: =IF(NOT(ISBLANK(Лист1!G11)),Лист1!$D11,0) -> 1.6 | D10: =IF(NOT(ISBLANK(Лист1!H11)),Лист1!$D11,0) -> 1.6 | E10: =IF(NOT(ISBLANK(Лист1!I11)),Лист1!$D11,0) -> 1.6 | F10: =IF(NOT(ISBLANK(Лист1!J11)),Лист1!$D11,0) -> 1.6 | G10: =IF(NOT(ISBLANK(Лист1!K11)),Лист1!$D11,0) -> 1.6 | H10: =IF(NOT(ISBLANK(Лист1!L11)),Лист1!$D11,0) -> 1.6 | ... L10: =IF(NOT(ISBLANK(Лист1!P11)),Лист1!$D11,0) -> 1.6
A11: =IF(NOT(ISBLANK(Лист1!E12)),Лист1!$D12,0) -> 1.6 | B11: =IF(NOT(ISBLANK(Лист1!F12)),Лист1!$D12,0) -> 1.6 | C11: =IF(NOT(ISBLANK(Лист1!G12)),Лист1!$D12,0) -> 1.6 | D11: =IF(NOT(ISBLANK(Лист1!H12)),Лист1!$D12,0) -> 1.6 | E11: =IF(NOT(ISBLANK(Лист1!I12)),Лист1!$D12,0) -> 1.6 | F11: =IF(NOT(ISBLANK(Лист1!J12)),Лист1!$D12,0) -> 1.6 | G11: =IF(NOT(ISBLANK(Лист1!K12)),Лист1!$D12,0) -> 1.6 | H11: =IF(NOT(ISBLANK(Лист1!L12)),Лист1!$D12,0) -> 1.6 | ... L11: =IF(NOT(ISBLANK(Лист1!P12)),Лист1!$D12,0) -> 1.6
A12: =IF(NOT(ISBLANK(Лист1!E13)),Лист1!$D13,0) -> 0 | B12: =IF(NOT(ISBLANK(Лист1!F13)),Лист1!$D13,0) -> 0 | C12: =IF(NOT(ISBLANK(Лист1!G13)),Лист1!$D13,0) -> 0 | D12: =IF(NOT(ISBLANK(Лист1!H13)),Лист1!$D13,0) -> 0 | E12: =IF(NOT(ISBLANK(Лист1!I13)),Лист1!$D13,0) -> 0 | F12: =IF(NOT(ISBLANK(Лист1!J13)),Лист1!$D13,0) -> 0 | G12: =IF(NOT(ISBLANK(Лист1!K13)),Лист1!$D13,0) -> 0 | H12: =IF(NOT(ISBLANK(Лист1!L13)),Лист1!$D13,0) -> 0 | ... L12: =IF(NOT(ISBLANK(Лист1!P13)),Лист1!$D13,0) -> 0
... A57: =IF(NOT(ISBLANK(Лист1!E58)),Лист1!$D58,0) -> 2.89 | B57: =IF(NOT(ISBLANK(Лист1!F58)),Лист1!$D58,0) -> 2.89 | C57: =IF(NOT(ISBLANK(Лист1!G58)),Лист1!$D58,0) -> 2.89 | D57: =IF(NOT(ISBLANK(Лист1!H58)),Лист1!$D58,0) -> 2.89 | E57: =IF(NOT(ISBLANK(Лист1!I58)),Лист1!$D58,0) -> 2.89 | F57: =IF(NOT(ISBLANK(Лист1!J58)),Лист1!$D58,0) -> 2.89 | G57: =IF(NOT(ISBLANK(Лист1!K58)),Лист1!$D58,0) -> 2.89 | H57: =IF(NOT(ISBLANK(Лист1!L58)),Лист1!$D58,0) -> 2.89 | ... L57: =IF(NOT(ISBLANK(Лист1!P58)),Лист1!$D58,0) -> 2.89
A58: =SUM(A1:A57) -> 61.14 | B58: =SUM(B1:B57) -> 61.14 | C58: =SUM(C1:C57) -> 61.14 | D58: =SUM(D1:D57) -> 61.14 | E58: =SUM(E1:E57) -> 61.14 | F58: =SUM(F1:F57) -> 61.14 | G58: =SUM(G1:G57) -> 61.14 | H58: =SUM(H1:H57) -> 61.14 | ... L58: =SUM(L1:L57) -> 61.14
A59: =1741.1*A58/100 -> 1064.5085

Sheet за
A1: =IF(Лист1!E2="за",Лист1!$D2,0) -> 1.63 | B1: =IF(Лист1!F2="за",Лист1!$D2,0) -> 1.63 | C1: =IF(Лист1!G2="за",Лист1!$D2,0) -> 1.63 | D1: =IF(Лист1!H2="за",Лист1!$D2,0) -> 1.63 | E1: =IF(Лист1!I2="за",Лист1!$D2,0) -> 0 | F1: =IF(Лист1!J2="за",Лист1!$D2,0) -> 1.63 | G1: =IF(Лист1!K2="за",Лист1!$D2,0) -> 1.63 | H1: =IF(Лист1!L2="за",Лист1!$D2,0) -> 0 | ... L1: =IF(Лист1!P2="за",Лист1!$D2,0) -> 0
A2: =IF(Лист1!E3="за",Лист1!$D3,0) -> 1.63 | B2: =IF(Лист1!F3="за",Лист1!$D3,0) -> 1.63 | C2: =IF(Лист1!G3="за",Лист1!$D3,0) -> 1.63 | D2: =IF(Лист1!H3="за",Лист1!$D3,0) -> 1.63 | E2: =IF(Лист1!I3="за",Лист1!$D3,0) -> 0 | F2: =IF(Лист1!J3="за",Лист1!$D3,0) -> 1.63 | G2: =IF(Лист1!K3="за",Лист1!$D3,0) -> 1.63 | H2: =IF(Лист1!L3="за",Лист1!$D3,0) -> 0 | ... L2: =IF(Лист1!P3="за",Лист1!$D3,0) -> 0
A3: =IF(Лист1!E4="за",Лист1!$D4,0) -> 2 | B3: =IF(Лист1!F4="за",Лист1!$D4,0) -> 2 | C3: =IF(Лист1!G4="за",Лист1!$D4,0) -> 2 | D3: =IF(Лист1!H4="за",Лист1!$D4,0) -> 2 | E3: =IF(Лист1!I4="за",Лист1!$D4,0) -> 2 | F3: =IF(Лист1!J4="за",Лист1!$D4,0) -> 2 | G3: =IF(Лист1!K4="за",Лист1!$D4,0) -> 2 | H3: =IF(Лист1!L4="за",Лист1!$D4,0) -> 0 | ... L3: =IF(Лист1!P4="за",Лист1!$D4,0) -> 2
A4: =IF(Лист1!E5="за",Лист1!$D5,0) -> 2.04 | B4: =IF(Лист1!F5="за",Лист1!$D5,0) -> 2.04 | C4: =IF(Лист1!G5="за",Лист1!$D5,0) -> 2.04 | D4: =IF(Лист1!H5="за",Лист1!$D5,0) -> 2.04 | E4: =IF(Лист1!I5="за",Лист1!$D5,0) -> 2.04 | F4: =IF(Лист1!J5="за",Лист1!$D5,0) -> 2.04 | G4: =IF(Лист1!K5="за",Лист1!$D5,0) -> 2.04 | H4: =IF(Лист1!L5="за",Лист1!$D5,0) -> 0 | ... L4: =IF(Лист1!P5="за",Лист1!$D5,0) -> 2.04
A5: =IF(Лист1!E6="за",Лист1!$D6,0) -> 1.51 | B5: =IF(Лист1!F6="за",Лист1!$D6,0) -> 1.51 | C5: =IF(Лист1!G6="за",Лист1!$D6,0) -> 0 | D5: =IF(Лист1!H6="за",Лист1!$D6,0) -> 0 | E5: =IF(Лист1!I6="за",Лист1!$D6,0) -> 0 | F5: =IF(Лист1!J6="за",Лист1!$D6,0) -> 0 | G5: =IF(Лист1!K6="за",Лист1!$D6,0) -> 1.51 | H5: =IF(Лист1!L6="за",Лист1!$D6,0) -> 0 | ... L5: =IF(Лист1!P6="за",Лист1!$D6,0) -> 1.51
A6: =IF(Лист1!E7="за",Лист1!$D7,0) -> 1.51 | B6: =IF(Лист1!F7="за",Лист1!$D7,0) -> 1.51 | C6: =IF(Лист1!G7="за",Лист1!$D7,0) -> 0 | D6: =IF(Лист1!H7="за",Лист1!$D7,0) -> 0 | E6: =IF(Лист1!I7="за",Лист1!$D7,0) -> 0 | F6: =IF(Лист1!J7="за",Лист1!$D7,0) -> 0 | G6: =IF(Лист1!K7="за",Лист1!$D7,0) -> 1.51 | H6: =IF(Лист1!L7="за",Лист1!$D7,0) -> 0 | ... L6: =IF(Лист1!P7="за",Лист1!$D7,0) -> 1.51
A7: =IF(Лист1!E8="за",Лист1!$D8,0) -> 2.15 | B7: =IF(Лист1!F8="за",Лист1!$D8,0) -> 2.15 | C7: =IF(Лист1!G8="за",Лист1!$D8,0) -> 2.15 | D7: =IF(Лист1!H8="за",Лист1!$D8,0) -> 2.15 | E7: =IF(Лист1!I8="за",Лист1!$D8,0) -> 2.15 | F7: =IF(Лист1!J8="за",Лист1!$D8,0) -> 2.15 | G7: =IF(Лист1!K8="за",Лист1!$D8,0) -> 0 | H7: =IF(Лист1!L8="за",Лист1!$D8,0) -> 0 | ... L7: =IF(Лист1!P8="за",Лист1!$D8,0) -> 2.15
A8: =IF(Лист1!E9="за",Лист1!$D9,0) -> 1.36 | B8: =IF(Лист1!F9="за",Лист1!$D9,0) -> 1.36 | C8: =IF(Лист1!G9="за",Лист1!$D9,0) -> 1.36 | D8: =IF(Лист1!H9="за",Лист1!$D9,0) -> 1.36 | E8: =IF(Лист1!I9="за",Лист1!$D9,0) -> 1.36 | F8: =IF(Лист1!J9="за",Лист1!$D9,0) -> 1.36 | G8: =IF(Лист1!K9="за",Лист1!$D9,0) -> 1.36 | H8: =IF(Лист1!L9="за",Лист1!$D9,0) -> 0 | ... L8: =IF(Лист1!P9="за",Лист1!$D9,0) -> 1.36
A9: =IF(Лист1!E10="за",Лист1!$D10,0) -> 1.36 | B9: =IF(Лист1!F10="за",Лист1!$D10,0) -> 1.36 | C9: =IF(Лист1!G10="за",Лист1!$D10,0) -> 1.36 | D9: =IF(Лист1!H10="за",Лист1!$D10,0) -> 1.36 | E9: =IF(Лист1!I10="за",Лист1!$D10,0) -> 1.36 | F9: =IF(Лист1!J10="за",Лист1!$D10,0) -> 1.36 | G9: =IF(Лист1!K10="за",Лист1!$D10,0) -> 1.36 | H9: =IF(Лист1!L10="за",Лист1!$D10,0) -> 0 | ... L9: =IF(Лист1!P10="за",Лист1!$D10,0) -> 1.36
A10: =IF(Лист1!E11="за",Лист1!$D11,0) -> 1.6 | B10: =IF(Лист1!F11="за",Лист1!$D11,0) -> 0 | C10: =IF(Лист1!G11="за",Лист1!$D11,0) -> 1.6 | D10: =IF(Лист1!H11="за",Лист1!$D11,0) -> 1.6 | E10: =IF(Лист1!I11="за",Лист1!$D11,0) -> 1.6 | F10: =IF(Лист1!J11="за",Лист1!$D11,0) -> 1.6 | G10: =IF(Лист1!K11="за",Лист1!$D11,0) -> 1.6 | H10: =IF(Лист1!L11="за",Лист1!$D11,0) -> 0 | ... L10: =IF(Лист1!P11="за",Лист1!$D11,0) -> 1.6
A11: =IF(Лист1!E12="за",Лист1!$D12,0) -> 1.6 | B11: =IF(Лист1!F12="за",Лист1!$D12,0) -> 0 | C11: =IF(Лист1!G12="за",Лист1!$D12,0) -> 1.6 | D11: =IF(Лист1!H12="за",Лист1!$D12,0) -> 1.6 | E11: =IF(Лист1!I12="за",Лист1!$D12,0) -> 1.6 | F11: =IF(Лист1!J12="за",Лист1!$D12,0) -> 1.6 | G11: =IF(Лист1!K12="за",Лист1!$D12,0) -> 1.6 | H11: =IF(Лист1!L12="за",Лист1!$D12,0) -> 0 | ... L11: =IF(Лист1!P12="за",Лист1!$D12,0) -> 1.6
A12: =IF(Лист1!E13="за",Лист1!$D13,0) -> 0 | B12: =IF(Лист1!F13="за",Лист1!$D13,0) -> 0 | C12: =IF(Лист1!G13="за",Лист1!$D13,0) -> 0 | D12: =IF(Лист1!H13="за",Лист1!$D13,0) -> 0 | E12: =IF(Лист1!I13="за",Лист1!$D13,0) -> 0 | F12: =IF(Лист1!J13="за",Лист1!$D13,0) -> 0 | G12: =IF(Лист1!K13="за",Лист1!$D13,0) -> 0 | H12: =IF(Лист1!L13="за",Лист1!$D13,0) -> 0 | ... L12: =IF(Лист1!P13="за",Лист1!$D13,0) -> 0
... A57: =IF(Лист1!E58="за",Лист1!$D58,0) -> 2.89 | B57: =IF(Лист1!F58="за",Лист1!$D58,0) -> 2.89 | C57: =IF(Лист1!G58="за",Лист1!$D58,0) -> 2.89 | D57: =IF(Лист1!H58="за",Лист1!$D58,0) -> 2.89 | E57: =IF(Лист1!I58="за",Лист1!$D58,0) -> 2.89 | F57: =IF(Лист1!J58="за",Лист1!$D58,0) -> 2.89 | G57: =IF(Лист1!K58="за",Лист1!$D58,0) -> 2.89 | H57: =IF(Лист1!L58="за",Лист1!$D58,0) -> 2.89 | ... L57: =IF(Лист1!P58="за",Лист1!$D58,0) -> 2.89
A58: =SUM(A1:A57) -> 56.99 | B58: =SUM(B1:B57) -> 55.79 | C58: =SUM(C1:C57) -> 53.97 | D58: =SUM(D1:D57) -> 55.97 | E58: =SUM(E1:E57) -> 48.68 | F58: =SUM(F1:F57) -> 53.97 | G58: =SUM(G1:G57) -> 58.99 | H58: =SUM(H1:H57) -> 25.38 | ... L58: =SUM(L1:L57) -> 49.71

Sheet против
A1: =IF(Лист1!E2="против",Лист1!$D2,0) -> 0 | B1: =IF(Лист1!F2="против",Лист1!$D2,0) -> 0 | C1: =IF(Лист1!G2="против",Лист1!$D2,0) -> 0 | D1: =IF(Лист1!H2="против",Лист1!$D2,0) -> 0 | E1: =IF(Лист1!I2="против",Лист1!$D2,0) -> 0 | F1: =IF(Лист1!J2="против",Лист1!$D2,0) -> 0 | G1: =IF(Лист1!K2="против",Лист1!$D2,0) -> 0 | H1: =IF(Лист1!L2="против",Лист1!$D2,0) -> 1.63 | ... L1: =IF(Лист1!P2="против",Лист1!$D2,0) -> 1.63
A2: =IF(Лист1!E3="против",Лист1!$D3,0) -> 0 | B2: =IF(Лист1!F3="против",Лист1!$D3,0) -> 0 | C2: =IF(Лист1!G3="против",Лист1!$D3,0) -> 0 | D2: =IF(Лист1!H3="против",Лист1!$D3,0) -> 0 | E2: =IF(Лист1!I3="против",Лист1!$D3,0) -> 0 | F2: =IF(Лист1!J3="против",Лист1!$D3,0) -> 0 | G2: =IF(Лист1!K3="против",Лист1!$D3,0) -> 0 | H2: =IF(Лист1!L3="против",Лист1!$D3,0) -> 1.63 | ... L2: =IF(Лист1!P3="против",Лист1!$D3,0) -> 1.63
A3: =IF(Лист1!E4="против",Лист1!$D4,0) -> 0 | B3: =IF(Лист1!F4="против",Лист1!$D4,0) -> 0 | C3: =IF(Лист1!G4="против",Лист1!$D4,0) -> 0 | D3: =IF(Лист1!H4="против",Лист1!$D4,0) -> 0 | E3: =IF(Лист1!I4="против",Лист1!$D4,0) -> 0 | F3: =IF(Лист1!J4="против",Лист1!$D4,0) -> 0 | G3: =IF(Лист1!K4="против",Лист1!$D4,0) -> 0 | H3: =IF(Лист1!L4="против",Лист1!$D4,0) -> 2 | ... L3: =IF(Лист1!P4="против",Лист1!$D4,0) -> 0
A4: =IF(Лист1!E5="против",Лист1!$D5,0) -> 0 | B4: =IF(Лист1!F5="против",Лист1!$D5,0) -> 0 | C4: =IF(Лист1!G5="против",Лист1!$D5,0) -> 0 | D4: =IF(Лист1!H5="против",Лист1!$D5,0) -> 0 | E4: =IF(Лист1!I5="против",Лист1!$D5,0) -> 0 | F4: =IF(Лист1!J5="против",Лист1!$D5,0) -> 0 | G4: =IF(Лист1!K5="против",Лист1!$D5,0) -> 0 | H4: =IF(Лист1!L5="против",Лист1!$D5,0) -> 2.04 | ... L4: =IF(Лист1!P5="против",Лист1!$D5,0) -> 0
A5: =IF(Лист1!E6="против",Лист1!$D6,0) -> 0 | B5: =IF(Лист1!F6="против",Лист1!$D6,0) -> 0 | C5: =IF(Лист1!G6="против",Лист1!$D6,0) -> 0 | D5: =IF(Лист1!H6="против",Лист1!$D6,0) -> 0 | E5: =IF(Лист1!I6="против",Лист1!$D6,0) -> 0 | F5: =IF(Лист1!J6="против",Лист1!$D6,0) -> 0 | G5: =IF(Лист1!K6="против",Лист1!$D6,0) -> 0 | H5: =IF(Лист1!L6="против",Лист1!$D6,0) -> 1.51 | ... L5: =IF(Лист1!P6="против",Лист1!$D6,0) -> 0
A6: =IF(Лист1!E7="против",Лист1!$D7,0) -> 0 | B6: =IF(Лист1!F7="против",Лист1!$D7,0) -> 0 | C6: =IF(Лист1!G7="против",Лист1!$D7,0) -> 0 | D6: =IF(Лист1!H7="против",Лист1!$D7,0) -> 0 | E6: =IF(Лист1!I7="против",Лист1!$D7,0) -> 0 | F6: =IF(Лист1!J7="против",Лист1!$D7,0) -> 0 | G6: =IF(Лист1!K7="против",Лист1!$D7,0) -> 0 | H6: =IF(Лист1!L7="против",Лист1!$D7,0) -> 1.51 | ... L6: =IF(Лист1!P7="против",Лист1!$D7,0) -> 0
A7: =IF(Лист1!E8="против",Лист1!$D8,0) -> 0 | B7: =IF(Лист1!F8="против",Лист1!$D8,0) -> 0 | C7: =IF(Лист1!G8="против",Лист1!$D8,0) -> 0 | D7: =IF(Лист1!H8="против",Лист1!$D8,0) -> 0 | E7: =IF(Лист1!I8="против",Лист1!$D8,0) -> 0 | F7: =IF(Лист1!J8="против",Лист1!$D8,0) -> 0 | G7: =IF(Лист1!K8="против",Лист1!$D8,0) -> 0 | H7: =IF(Лист1!L8="против",Лист1!$D8,0) -> 0 | ... L7: =IF(Лист1!P8="против",Лист1!$D8,0) -> 0
A8: =IF(Лист1!E9="против",Лист1!$D9,0) -> 0 | B8: =IF(Лист1!F9="против",Лист1!$D9,0) -> 0 | C8: =IF(Лист1!G9="против",Лист1!$D9,0) -> 0 | D8: =IF(Лист1!H9="против",Лист1!$D9,0) -> 0 | E8: =IF(Лист1!I9="против",Лист1!$D9,0) -> 0 | F8: =IF(Лист1!J9="против",Лист1!$D9,0) -> 0 | G8: =IF(Лист1!K9="против",Лист1!$D9,0) -> 0 | H8: =IF(Лист1!L9="против",Лист1!$D9,0) -> 1.36 | ... L8: =IF(Лист1!P9="против",Лист1!$D9,0) -> 0
A9: =IF(Лист1!E10="против",Лист1!$D10,0) -> 0 | B9: =IF(Лист1!F10="против",Лист1!$D10,0) -> 0 | C9: =IF(Лист1!G10="против",Лист1!$D10,0) -> 0 | D9: =IF(Лист1!H10="против",Лист1!$D10,0) -> 0 | E9: =IF(Лист1!I10="против",Лист1!$D10,0) -> 0 | F9: =IF(Лист1!J10="против",Лист1!$D10,0) -> 0 | G9: =IF(Лист1!K10="против",Лист1!$D10,0) -> 0 | H9: =IF(Лист1!L10="против",Лист1!$D10,0) -> 1.36 | ... L9: =IF(Лист1!P10="против",Лист1!$D10,0) -> 0
A10: =IF(Лист1!E11="против",Лист1!$D11,0) -> 0 | B10: =IF(Лист1!F11="против",Лист1!$D11,0) -> 0 | C10: =IF(Лист1!G11="против",Лист1!$D11,0) -> 0 | D10: =IF(Лист1!H11="против",Лист1!$D11,0) -> 0 | E10: =IF(Лист1!I11="против",Лист1!$D11,0) -> 0 | F10: =IF(Лист1!J11="против",Лист1!$D11,0) -> 0 | G10: =IF(Лист1!K11="против",Лист1!$D11,0) -> 0 | H10: =IF(Лист1!L11="против",Лист1!$D11,0) -> 1.6 | ... L10: =IF(Лист1!P11="против",Лист1!$D11,0) -> 0
A11: =IF(Лист1!E12="против",Лист1!$D12,0) -> 0 | B11: =IF(Лист1!F12="против",Лист1!$D12,0) -> 0 | C11: =IF(Лист1!G12="против",Лист1!$D12,0) -> 0 | D11: =IF(Лист1!H12="против",Лист1!$D12,0) -> 0 | E11: =IF(Лист1!I12="против",Лист1!$D12,0) -> 0 | F11: =IF(Лист1!J12="против",Лист1!$D12,0) -> 0 | G11: =IF(Лист1!K12="против",Лист1!$D12,0) -> 0 | H11: =IF(Лист1!L12="против",Лист1!$D12,0) -> 1.6 | ... L11: =IF(Лист1!P12="против",Лист1!$D12,0) -> 0
A12: =IF(Лист1!E13="против",Лист1!$D13,0) -> 0 | B12: =IF(Лист1!F13="против",Лист1!$D13,0) -> 0 | C12: =IF(Лист1!G13="против",Лист1!$D13,0) -> 0 | D12: =IF(Лист1!H13="против",Лист1!$D13,0) -> 0 | E12: =IF(Лист1!I13="против",Лист1!$D13,0) -> 0 | F12: =IF(Лист1!J13="против",Лист1!$D13,0) -> 0 | G12: =IF(Лист1!K13="против",Лист1!$D13,0) -> 0 | H12: =IF(Лист1!L13="против",Лист1!$D13,0) -> 0 | ... L12: =IF(Лист1!P13="против",Лист1!$D13,0) -> 0
... A57: =IF(Лист1!E58="против",Лист1!$D58,0) -> 0 | B57: =IF(Лист1!F58="против",Лист1!$D58,0) -> 0 | C57: =IF(Лист1!G58="против",Лист1!$D58,0) -> 0 | D57: =IF(Лист1!H58="против",Лист1!$D58,0) -> 0 | E57: =IF(Лист1!I58="против",Лист1!$D58,0) -> 0 | F57: =IF(Лист1!J58="против",Лист1!$D58,0) -> 0 | G57: =IF(Лист1!K58="против",Лист1!$D58,0) -> 0 | H57: =IF(Лист1!L58="против",Лист1!$D58,0) -> 0 | ... L57: =IF(Лист1!P58="против",Лист1!$D58,0) -> 0
A58: =SUM(A1:A57) -> 4.15 | B58: =SUM(B1:B57) -> 0 | C58: =SUM(C1:C57) -> 2 | D58: =SUM(D1:D57) -> 0 | E58: =SUM(E1:E57) -> 4.15 | F58: =SUM(F1:F57) -> 4.15 | G58: =SUM(G1:G57) -> 0 | H58: =SUM(H1:H57) -> 28.58 | ... L58: =SUM(L1:L57) -> 5.26

Sheet воздержался
A1: =IF(Лист1!E2="воздержался",Лист1!$D2,0) -> 0 | B1: =IF(Лист1!F2="воздержался",Лист1!$D2,0) -> 0 | C1: =IF(Лист1!G2="воздержался",Лист1!$D2,0) -> 0 | D1: =IF(Лист1!H2="воздержался",Лист1!$D2,0) -> 0 | E1: =IF(Лист1!I2="воздержался",Лист1!$D2,0) -> 1.63 | F1: =IF(Лист1!J2="воздержался",Лист1!$D2,0) -> 0 | G1: =IF(Лист1!K2="воздержался",Лист1!$D2,0) -> 0 | H1: =IF(Лист1!L2="воздержался",Лист1!$D2,0) -> 0 | ... L1: =IF(Лист1!P2="воздержался",Лист1!$D2,0) -> 0
A2: =IF(Лист1!E3="воздержался",Лист1!$D3,0) -> 0 | B2: =IF(Лист1!F3="воздержался",Лист1!$D3,0) -> 0 | C2: =IF(Лист1!G3="воздержался",Лист1!$D3,0) -> 0 | D2: =IF(Лист1!H3="воздержался",Лист1!$D3,0) -> 0 | E2: =IF(Лист1!I3="воздержался",Лист1!$D3,0) -> 1.63 | F2: =IF(Лист1!J3="воздержался",Лист1!$D3,0) -> 0 | G2: =IF(Лист1!K3="воздержался",Лист1!$D3,0) -> 0 | H2: =IF(Лист1!L3="воздержался",Лист1!$D3,0) -> 0 | ... L2: =IF(Лист1!P3="воздержался",Лист1!$D3,0) -> 0
A3: =IF(Лист1!E4="воздержался",Лист1!$D4,0) -> 0 | B3: =IF(Лист1!F4="воздержался",Лист1!$D4,0) -> 0 | C3: =IF(Лист1!G4="воздержался",Лист1!$D4,0) -> 0 | D3: =IF(Лист1!H4="воздержался",Лист1!$D4,0) -> 0 | E3: =IF(Лист1!I4="воздержался",Лист1!$D4,0) -> 0 | F3: =IF(Лист1!J4="воздержался",Лист1!$D4,0) -> 0 | G3: =IF(Лист1!K4="воздержался",Лист1!$D4,0) -> 0 | H3: =IF(Лист1!L4="воздержался",Лист1!$D4,0) -> 0 | ... L3: =IF(Лист1!P4="воздержался",Лист1!$D4,0) -> 0
A4: =IF(Лист1!E5="воздержался",Лист1!$D5,0) -> 0 | B4: =IF(Лист1!F5="воздержался",Лист1!$D5,0) -> 0 | C4: =IF(Лист1!G5="воздержался",Лист1!$D5,0) -> 0 | D4: =IF(Лист1!H5="воздержался",Лист1!$D5,0) -> 0 | E4: =IF(Лист1!I5="воздержался",Лист1!$D5,0) -> 0 | F4: =IF(Лист1!J5="воздержался",Лист1!$D5,0) -> 0 | G4: =IF(Лист1!K5="воздержался",Лист1!$D5,0) -> 0 | H4: =IF(Лист1!L5="воздержался",Лист1!$D5,0) -> 0 | ... L4: =IF(Лист1!P5="воздержался",Лист1!$D5,0) -> 0
A5: =IF(Лист1!E6="воздержался",Лист1!$D6,0) -> 0 | B5: =IF(Лист1!F6="воздержался",Лист1!$D6,0) -> 0 | C5: =IF(Лист1!G6="воздержался",Лист1!$D6,0) -> 1.51 | D5: =IF(Лист1!H6="воздержался",Лист1!$D6,0) -> 1.51 | E5: =IF(Лист1!I6="воздержался",Лист1!$D6,0) -> 1.51 | F5: =IF(Лист1!J6="воздержался",Лист1!$D6,0) -> 1.51 | G5: =IF(Лист1!K6="воздержался",Лист1!$D6,0) -> 0 | H5: =IF(Лист1!L6="воздержался",Лист1!$D6,0) -> 0 | ... L5: =IF(Лист1!P6="воздержался",Лист1!$D6,0) -> 0
A6: =IF(Лист1!E7="воздержался",Лист1!$D7,0) -> 0 | B6: =IF(Лист1!F7="воздержался",Лист1!$D7,0) -> 0 | C6: =IF(Лист1!G7="воздержался",Лист1!$D7,0) -> 1.51 | D6: =IF(Лист1!H7="воздержался",Лист1!$D7,0) -> 1.51 | E6: =IF(Лист1!I7="воздержался",Лист1!$D7,0) -> 1.51 | F6: =IF(Лист1!J7="воздержался",Лист1!$D7,0) -> 1.51 | G6: =IF(Лист1!K7="воздержался",Лист1!$D7,0) -> 0 | H6: =IF(Лист1!L7="воздержался",Лист1!$D7,0) -> 0 | ... L6: =IF(Лист1!P7="воздержался",Лист1!$D7,0) -> 0
A7: =IF(Лист1!E8="воздержался",Лист1!$D8,0) -> 0 | B7: =IF(Лист1!F8="воздержался",Лист1!$D8,0) -> 0 | C7: =IF(Лист1!G8="воздержался",Лист1!$D8,0) -> 0 | D7: =IF(Лист1!H8="воздержался",Лист1!$D8,0) -> 0 | E7: =IF(Лист1!I8="воздержался",Лист1!$D8,0) -> 0 | F7: =IF(Лист1!J8="воздержался",Лист1!$D8,0) -> 0 | G7: =IF(Лист1!K8="воздержался",Лист1!$D8,0) -> 2.15 | H7: =IF(Лист1!L8="воздержался",Лист1!$D8,0) -> 2.15 | ... L7: =IF(Лист1!P8="воздержался",Лист1!$D8,0) -> 0
A8: =IF(Лист1!E9="воздержался",Лист1!$D9,0) -> 0 | B8: =IF(Лист1!F9="воздержался",Лист1!$D9,0) -> 0 | C8: =IF(Лист1!G9="воздержался",Лист1!$D9,0) -> 0 | D8: =IF(Лист1!H9="воздержался",Лист1!$D9,0) -> 0 | E8: =IF(Лист1!I9="воздержался",Лист1!$D9,0) -> 0 | F8: =IF(Лист1!J9="воздержался",Лист1!$D9,0) -> 0 | G8: =IF(Лист1!K9="воздержался",Лист1!$D9,0) -> 0 | H8: =IF(Лист1!L9="воздержался",Лист1!$D9,0) -> 0 | ... L8: =IF(Лист1!P9="воздержался",Лист1!$D9,0) -> 0
A9: =IF(Лист1!E10="воздержался",Лист1!$D10,0) -> 0 | B9: =IF(Лист1!F10="воздержался",Лист1!$D10,0) -> 0 | C9: =IF(Лист1!G10="воздержался",Лист1!$D10,0) -> 0 | D9: =IF(Лист1!H10="воздержался",Лист1!$D10,0) -> 0 | E9: =IF(Лист1!I10="воздержался",Лист1!$D10,0) -> 0 | F9: =IF(Лист1!J10="воздержался",Лист1!$D10,0) -> 0 | G9: =IF(Лист1!K10="воздержался",Лист1!$D10,0) -> 0 | H9: =IF(Лист1!L10="воздержался",Лист1!$D10,0) -> 0 | ... L9: =IF(Лист1!P10="воздержался",Лист1!$D10,0) -> 0
A10: =IF(Лист1!E11="воздержался",Лист1!$D11,0) -> 0 | B10: =IF(Лист1!F11="воздержался",Лист1!$D11,0) -> 1.6 | C10: =IF(Лист1!G11="воздержался",Лист1!$D11,0) -> 0 | D10: =IF(Лист1!H11="воздержался",Лист1!$D11,0) -> 0 | E10: =IF(Лист1!I11="воздержался",Лист1!$D11,0) -> 0 | F10: =IF(Лист1!J11="воздержался",Лист1!$D11,0) -> 0 | G10: =IF(Лист1!K11="воздержался",Лист1!$D11,0) -> 0 | H10: =IF(Лист1!L11="воздержался",Лист1!$D11,0) -> 0 | ... L10: =IF(Лист1!P11="воздержался",Лист1!$D11,0) -> 0
A11: =IF(Лист1!E12="воздержался",Лист1!$D12,0) -> 0 | B11: =IF(Лист1!F12="воздержался",Лист1!$D12,0) -> 1.6 | C11: =IF(Лист1!G12="воздержался",Лист1!$D12,0) -> 0 | D11: =IF(Лист1!H12="воздержался",Лист1!$D12,0) -> 0 | E11: =IF(Лист1!I12="воздержался",Лист1!$D12,0) -> 0 | F11: =IF(Лист1!J12="воздержался",Лист1!$D12,0) -> 0 | G11: =IF(Лист1!K12="воздержался",Лист1!$D12,0) -> 0 | H11: =IF(Лист1!L12="воздержался",Лист1!$D12,0) -> 0 | ... L11: =IF(Лист1!P12="воздержался",Лист1!$D12,0) -> 0
A12: =IF(Лист1!E13="воздержался",Лист1!$D13,0) -> 0 | B12: =IF(Лист1!F13="воздержался",Лист1!$D13,0) -> 0 | C12: =IF(Лист1!G13="воздержался",Лист1!$D13,0) -> 0 | D12: =IF(Лист1!H13="воздержался",Лист1!$D13,0) -> 0 | E12: =IF(Лист1!I13="воздержался",Лист1!$D13,0) -> 0 | F12: =IF(Лист1!J13="воздержался",Лист1!$D13,0) -> 0 | G12: =IF(Лист1!K13="воздержался",Лист1!$D13,0) -> 0 | H12: =IF(Лист1!L13="воздержался",Лист1!$D13,0) -> 0 | ... L12: =IF(Лист1!P13="воздержался",Лист1!$D13,0) -> 0
... A57: =IF(Лист1!E58="воздержался",Лист1!$D58,0) -> 0 | B57: =IF(Лист1!F58="воздержался",Лист1!$D58,0) -> 0 | C57: =IF(Лист1!G58="воздержался",Лист1!$D58,0) -> 0 | D57: =IF(Лист1!H58="воздержался",Лист1!$D58,0) -> 0 | E57: =IF(Лист1!I58="воздержался",Лист1!$D58,0) -> 0 | F57: =IF(Лист1!J58="воздержался",Лист1!$D58,0) -> 0 | G57: =IF(Лист1!K58="воздержался",Лист1!$D58,0) -> 0 | H57: =IF(Лист1!L58="воздержался",Лист1!$D58,0) -> 0 | ... L57: =IF(Лист1!P58="воздержался",Лист1!$D58,0) -> 0
A58: =SUM(A1:A57) -> 0 | B58: =SUM(B1:B57) -> 5.35 | C58: =SUM(C1:C57) -> 5.17 | D58: =SUM(D1:D57) -> 5.17 | E58: =SUM(E1:E57) -> 6.28 | F58: =SUM(F1:F57) -> 3.02 | G58: =SUM(G1:G57) -> 2.15 | H58: =SUM(H1:H57) -> 7.18 | ... L58: =SUM(L1:L57) -> 6.17
